<!-- /* Copyright 2020 The MathWorks, Inc. -->
<?xml version="1.0"?>
<sdf version="1.4">
  <world name="default">
    <include>
      <uri>model://ground_plane</uri>
    </include>

    <include>
      <uri>model://sun</uri>
    </include>

  <model name ='unit_box'>
    <pose>-5 -5 0.5 0 0 0</pose>
    <link name ='link'>
      <pose>0 0 0 0 0 0</pose>
      <collision name ='collision'>
        <geometry>
          <box><size>1 1 1</size></box>
        </geometry>
      </collision>
      <visual name ='visual'>
        <geometry>
          <box><size>1 1 1</size></box>
        </geometry>
      </visual>
    </link>
  </model>

   <model name = "2_body">
    
    <pose>0 2 0 0 0 0</pose>
    
    <link name = "base">
      <pose>0 0 0.1 0 0 0</pose>
      <visual name = "visual">
        <geometry>
          <cylinder>
            <radius>0.25</radius>
            <length>0.2</length>
          </cylinder>
        </geometry>
      </visual>
    </link>

    <link name = "follower">
      <pose>0 0 0.2 0 0 0</pose>
      <visual name = "visual">
        <geometry>
          <box>
            <size>0.1 0.1 0.1</size>
          </box>
        </geometry>
      </visual>
    </link>

    <joint name="base_joint" type ="fixed">
      <pose>0 2 0 0 0 0</pose>
      <parent>world</parent>
      <child>base</child>
    </joint>

    <joint name="follower_joint" type ="revolute">
      <pose>0 0 0 0 0 0</pose>
      <parent>base</parent>
      <child>follower</child>
      <axis>
        <xyz>0 0 1</xyz>
      </axis>
    </joint>
  </model>

  <model name = "3_body">
    
    <pose>2 0 0 0 0 0</pose>
    
    <link name = "base">
      <pose>0 0 0.1 0 0 0</pose>
      <visual name = "visual">
        <geometry>
          <cylinder>
            <radius>0.25</radius>
            <length>0.2</length>
          </cylinder>
        </geometry>
      </visual>
    </link>

    <link name = "follower">
      <pose>0 0 0.3 0 0 0</pose>
      <visual name = "visual">
        <geometry>
            <sphere>
              <radius>0.1</radius>
            </sphere>
        </geometry>
      </visual>
    </link>

    <joint name="base_joint" type ="fixed">
      <pose>0 2 0 0 0 0</pose>
      <parent>world</parent>
      <child>base</child>
    </joint>

    <joint name='follower_joint' type='revolute2'>
        <parent>base</parent>
        <child>follower</child>
        <axis>
          <xyz>0 1 0</xyz>
        </axis>
        <axis>
          <xyz>1 0 0</xyz>
        </axis>
    </joint>

  </model> 

 
  <model name='universal_joint'>
     <link name='parent_link'>
        <pose frame=''>0 0 0 0 0 0</pose>
        <inertial>
          <inertia>
            <ixx>0.0016667</ixx>
            <ixy>0</ixy>
            <ixz>0</ixz>
            <iyy>0.0016667</iyy>
            <iyz>0</iyz>
            <izz>0.0016667</izz>
          </inertia>
          <pose frame=''>0 0 0 0 0 0</pose>
          <mass>1</mass>
        </inertial>
        <collision name='parent_link_collision'>
          <geometry>
            <box>
              <size>0.1 0.1 0.1</size>
            </box>
          </geometry>
          <max_contacts>10</max_contacts>
        </collision>
        <visual name='parent_link_visual'>
          <geometry>
            <box>
              <size>0.1 0.1 0.1</size>
            </box>
          </geometry>
        </visual>
        <self_collide>0</self_collide>
        <enable_wind>0</enable_wind>
        <kinematic>0</kinematic>
      </link>

      <link name='child_link'>
        <pose frame=''>0 0 0.2 0 0 0 </pose>
        <inertial>
          <inertia>
            <ixx>0.0058333</ixx>
            <ixy>0</ixy>
            <ixz>0</ixz>
            <iyy>0.0058333</iyy>
            <iyz>0</iyz>
            <izz>0.00125</izz>
          </inertia>
          <pose frame=''>-0.02 0.02 0 0 0 0</pose>
          <mass>1</mass>
        </inertial>
        <collision name='child_link_collision'>
          <geometry>
            <cylinder>
              <radius>0.05</radius>
              <length>0.25</length>
            </cylinder>
          </geometry>
          <max_contacts>10</max_contacts>
        </collision>
        <visual name='child_link_visual'>
          <geometry>
            <cylinder>
              <radius>0.05</radius>
              <length>0.25</length>
            </cylinder>
          </geometry>
        </visual>
        <self_collide>0</self_collide>
        <enable_wind>0</enable_wind>
        <kinematic>0</kinematic>
      </link>
      <joint name='universal_joint' type='universal'>
        <parent>parent_link</parent>
        <child>child_link</child>
        <pose frame=''>0 0 0.2 0 0 0</pose>
      </joint>
   </model>

  
   <model name='two_wheel_vehicle'>
      <link name='base_link'>
        <pose frame=''>0.1 0 0.11 0 -0 0</pose>
        <inertial>
          <mass>0.0001</mass>
          <inertia>
            <ixx>0.07</ixx>
            <iyy>0.08</iyy>
            <izz>0.1</izz>
            <ixy>0</ixy>
            <ixz>0</ixz>
            <iyz>0</iyz>
          </inertia>
          <pose frame=''>0 0 0 0 -0 0</pose>
        </inertial>
        <collision name='collision'>
          <geometry>
            <box>
              <size>0.445 0.277 0.17</size>
            </box>
          </geometry>
          <max_contacts>10</max_contacts>
          <surface>
            <contact>
              <ode/>
            </contact>
            <bounce/>
            <friction>
              <torsional>
                <ode/>
              </torsional>
              <ode/>
            </friction>
          </surface>
        </collision>

        <visual name='visual'>
          <geometry>
            <cylinder>
              <radius>0.3</radius>
              <length>0.01</length>
            </cylinder>
          </geometry>
        </visual>
        <self_collide>0</self_collide>
        <enable_wind>0</enable_wind>
        <kinematic>0</kinematic>
      </link>
      <link name='right_wheel_link'>
        <pose frame=''>0.1 -0.17 0.11 -0 1.5707 1.5707</pose>
        <inertial>
          <mass>2</mass>
          <inertia>
            <ixx>0.0051</ixx>
            <iyy>0.0051</iyy>
            <izz>0.009</izz>
            <ixy>0</ixy>
            <ixz>0</ixz>
            <iyz>0</iyz>
          </inertia>
          <pose frame=''>0 0 0 0 -0 0</pose>
        </inertial>
        <collision name='collision'>
          <geometry>
            <cylinder>
              <radius>0.11</radius>
              <length>0.05</length>
            </cylinder>
          </geometry>
          <surface>
            <friction>
              <ode>
                <mu>100000</mu>
                <mu2>100000</mu2>
                <slip1>0</slip1>
                <slip2>0</slip2>
              </ode>
              <torsional>
                <ode/>
              </torsional>
            </friction>
            <contact>
              <ode/>
            </contact>
            <bounce/>
          </surface>
          <max_contacts>10</max_contacts>
        </collision>
        <visual name='visual'>
          <geometry>
            <cylinder>
              <radius>0.11</radius>
              <length>0.05</length>
            </cylinder>
          </geometry>
        </visual>
        <self_collide>0</self_collide>
        <enable_wind>0</enable_wind>
        <kinematic>0</kinematic>
      </link>
      <link name='left_wheel_link'>
        <pose frame=''>0.1 0.17 0.11 -0 1.5707 1.5707</pose>
        <inertial>
          <mass>2</mass>
          <inertia>
            <ixx>0.0051</ixx>
            <iyy>0.0051</iyy>
            <izz>0.009</izz>
            <ixy>0</ixy>
            <ixz>0</ixz>
            <iyz>0</iyz>
          </inertia>
          <pose frame=''>0 0 0 0 -0 0</pose>
        </inertial>
        <collision name='collision'>
          <geometry>
            <cylinder>
              <radius>0.11</radius>
              <length>0.05</length>
            </cylinder>
          </geometry>
          <surface>
            <friction>
              <ode>
                <mu>100000</mu>
                <mu2>100000</mu2>
                <slip1>0</slip1>
                <slip2>0</slip2>
              </ode>
              <torsional>
                <ode/>
              </torsional>
            </friction>
            <contact>
              <ode/>
            </contact>
            <bounce/>
          </surface>
          <max_contacts>10</max_contacts>
        </collision>
        <visual name='visual'>
          <geometry>
            <cylinder>
              <radius>0.11</radius>
              <length>0.05</length>
            </cylinder>
          </geometry>
        </visual>
        <self_collide>0</self_collide>
        <enable_wind>0</enable_wind>
        <kinematic>0</kinematic>
      </link>
      <joint name='left_wheel_joint' type='revolute'>
        <pose frame=''>0 0 -0.03 0 -0 0</pose>
        <child>left_wheel_link</child>
        <parent>base_link</parent>
        <axis>
          <xyz>0 1 0</xyz>
          <use_parent_model_frame>1</use_parent_model_frame>
          <limit>
            <lower>-1e+16</lower>
            <upper>1e+16</upper>
          </limit>
          <dynamics>
            <spring_reference>0</spring_reference>
            <spring_stiffness>0</spring_stiffness>
          </dynamics>
        </axis>
      </joint>
      <joint name='right_wheel_joint' type='revolute'>
        <pose frame=''>0 0 0.03 0 -0 0</pose>
        <child>right_wheel_link</child>
        <parent>base_link</parent>
        <axis>
          <xyz>0 1 0</xyz>
          <use_parent_model_frame>1</use_parent_model_frame>
          <limit>
            <lower>-1e+16</lower>
            <upper>1e+16</upper>
          </limit>
          <dynamics>
            <spring_reference>0</spring_reference>
            <spring_stiffness>0</spring_stiffness>
          </dynamics>
        </axis>
      </joint>
      <pose frame=''>-2.2482 -2.42165 0 0 -0 0</pose>
    </model>


    <plugin name="GazeboPlugin" filename="lib/libGazeboCoSimPlugin.so"><portNumber>14581</portNumber></plugin>
  </world>
</sdf>