<!-- /* Copyright 2019-2021 The MathWorks, Inc. -->
<?xml version="1.0"?>
<sdf version="1.4">
  <world name="default">
    <include>
      <uri>model://ground_plane</uri>
    </include>

    <include>
      <uri>model://sun</uri>
    </include>

   <model name ='unit_box'>
    <pose>0.0 0.0 0.5 0.0 0.0 0.0</pose>
    <link name ='link'>
      <pose>0.0 0.0 0.0 0.0 0.0 0.0</pose>
      <collision name ='collision'>
        <geometry>
          <box><size>1 1 1</size></box>
        </geometry>
      </collision>
      <visual name ='visual'>
        <geometry>
          <box><size>1 1 1</size></box>
        </geometry>
      </visual>
    </link>

      <joint type="revolute" name="joint">
		<pose>0.0 0.0 0.0 0.0 0.0 0.0</pose>
        <child>link</child>
        <parent>link</parent>
        <axis>
          <xyz>0 0 0</xyz>
        </axis>
      </joint>
   </model>
   
    <model name ='unit_boxA'>
    <pose>0.0 10.0 0.5 0.0 0.0 0.0</pose>
    <link name ='link0'></link>	
    <link name ='link'>
      <pose>0.0 0.0 0.0 0.0 0.0 0.0</pose>
      <collision name ='collision'>
        <geometry>
          <box><size>1 1 1</size></box>
        </geometry>
      </collision>
      <visual name ='visual'>
        <geometry>
          <box><size>1 1 1</size></box>
        </geometry>
      </visual>
    </link>

      <joint type="revolute" name="joint">
		<pose>0.0 0.0 0.0 0.0 0.0 0.0</pose>
	<child>link0</child>
        <parent>link</parent>
        <axis>
          <xyz>0 0 0</xyz>
        </axis>
      </joint>
   </model>

    <model name ='unit_boxB'>
    <pose>0.0 15.0 0.5 0.0 0.0 0.0</pose>
    <link name ='link0'></link>
    <link name ='link'>
      <pose>0.0 0.0 0.0 0.0 0.0 0.0</pose>
      <collision name ='collision'>
        <geometry>
          <box><size>1 1 1</size></box>
        </geometry>
      </collision>
      <visual name ='visual'>
        <geometry>
          <box><size>1 1 1</size></box>
        </geometry>
      </visual>
    </link>

      <joint type="revolute" name="joint">
		<pose>0.0 0.0 0.0 0.0 0.0 0.0</pose>
	<child>link0</child>
        <parent>link</parent>
        <axis>
          <xyz>0 0 0</xyz>
        </axis>
      </joint>
   </model>

   <model name="camera0">
    <pose>0 1 0.05 0 0 0</pose>
    <link name="link">
      <inertial>
        <mass>0.1</mass>
        <inertia>
          <ixx>0.000166667</ixx>
          <iyy>0.000166667</iyy>
          <izz>0.000166667</izz>
        </inertia>
      </inertial>
      <collision name="collision">
        <geometry>
          <box>
            <size>0.1 0.1 0.1</size>
          </box>
        </geometry>
      </collision>
      <visual name="visual">
        <geometry>
          <box>
            <size>0.1 0.1 0.1</size>
          </box>
        </geometry>
      </visual>
      <sensor name="camera" type="camera">
        <camera>
          <horizontal_fov>1.047</horizontal_fov>
          <image>
            <width>320</width>
            <height>240</height>
          </image>
          <clip>
            <near>0.1</near>
            <far>100</far>
          </clip>
        </camera>
        <always_on>1</always_on>
        <update_rate>200</update_rate>
        <visualize>true</visualize>
      </sensor>
    </link>
  </model>

   <model name="camera1">
    <pose>0 2 0.05 0 0 0</pose>
    <link name="link">
      <inertial>
        <mass>0.1</mass>
        <inertia>
          <ixx>0.000166667</ixx>
          <iyy>0.000166667</iyy>
          <izz>0.000166667</izz>
        </inertia>
      </inertial>
      <collision name="collision">
        <geometry>
          <box>
            <size>0.1 0.1 0.1</size>
          </box>
        </geometry>
      </collision>
      <visual name="visual">
        <geometry>
          <box>
            <size>0.1 0.1 0.1</size>
          </box>
        </geometry>
      </visual>
      <sensor name="camera" type="camera">
        <camera>
          <horizontal_fov>1.047</horizontal_fov>
          <image>
            <width>320</width>
            <height>240</height>
          </image>
          <clip>
            <near>0.1</near>
            <far>100</far>
          </clip>
        </camera>
        <always_on>1</always_on>
        <update_rate>200</update_rate>
        <visualize>true</visualize>
      </sensor>
    </link>
  </model>

  <model name="depth_camera0">
    <link name="link">
      <pose>0 -1 0.05 0 0 0</pose>
      <inertial>
        <mass>0.1</mass>
        <inertia>
          <ixx>0.000166667</ixx>
          <iyy>0.000166667</iyy>
          <izz>0.000166667</izz>
        </inertia>
      </inertial>
      <collision name="collision">
        <geometry>
          <box>
            <size>0.1 0.1 0.1</size>
          </box>
        </geometry>
      </collision>
      <visual name="visual">
        <geometry>
          <box>
            <size>0.1 0.1 0.1</size>
          </box>
        </geometry>
      </visual>
      <sensor name="camera" type="depth">
        <camera>
          <horizontal_fov>1.047</horizontal_fov>
          <image>
            <width>320</width>
            <height>240</height>
          </image>
          <clip>
            <near>0.1</near>
            <far>100</far>
          </clip>
        </camera>
        <always_on>1</always_on>
        <update_rate>200</update_rate>
        <visualize>true</visualize>
      </sensor>
    </link>
  </model>

  <model name="depth_camera1">
    <link name="link">
      <pose>0 -2 0.05 0 0 0</pose>
      <inertial>
        <mass>0.1</mass>
        <inertia>
          <ixx>0.000166667</ixx>
          <iyy>0.000166667</iyy>
          <izz>0.000166667</izz>
        </inertia>
      </inertial>
      <collision name="collision">
        <geometry>
          <box>
            <size>0.1 0.1 0.1</size>
          </box>
        </geometry>
      </collision>
      <visual name="visual">
        <geometry>
          <box>
            <size>0.1 0.1 0.1</size>
          </box>
        </geometry>
      </visual>
      <sensor name="camera" type="depth">
        <camera>
          <horizontal_fov>1.047</horizontal_fov>
          <image>
            <width>320</width>
            <height>240</height>
          </image>
          <clip>
            <near>0.1</near>
            <far>100</far>
          </clip>
        </camera>
        <always_on>1</always_on>
        <update_rate>200</update_rate>
        <visualize>true</visualize>
      </sensor>
    </link>
  </model>

  <model name="imu0">
    <link name="link">
     <pose>-2 -1 0.05 0 0 0</pose>
      <inertial>
        <mass>0.1</mass>
      </inertial>
      <visual name="visual">
        <geometry>
          <box>
            <size>0.1 0.1 0.1</size>
          </box>
        </geometry>
      </visual>
      <collision name="collision">
        <geometry>
          <box>
            <size>0.1 0.1 0.1</size>
          </box>
        </geometry>
      </collision>
      <sensor name="imu" type="imu">
        <imu>
          <angular_velocity>
            <x>
              <noise type="gaussian">
                <mean>0.0</mean>
                <stddev>2e-4</stddev>
                <bias_mean>0.0000075</bias_mean>
                <bias_stddev>0.0000008</bias_stddev>
              </noise>
            </x>
            <y>
              <noise type="gaussian">
                <mean>0.0</mean>
                <stddev>2e-4</stddev>
                <bias_mean>0.0000075</bias_mean>
                <bias_stddev>0.0000008</bias_stddev>
              </noise>
            </y>
            <z>
              <noise type="gaussian">
                <mean>0.0</mean>
                <stddev>2e-4</stddev>
                <bias_mean>0.0000075</bias_mean>
                <bias_stddev>0.0000008</bias_stddev>
              </noise>
            </z>
          </angular_velocity>
          <linear_acceleration>
            <x>
              <noise type="gaussian">
                <mean>0.0</mean>
                <stddev>1.7e-2</stddev>
                <bias_mean>0.1</bias_mean>
                <bias_stddev>0.001</bias_stddev>
              </noise>
            </x>
            <y>
              <noise type="gaussian">
                <mean>0.0</mean>
                <stddev>1.7e-2</stddev>
                <bias_mean>0.1</bias_mean>
                <bias_stddev>0.001</bias_stddev>
              </noise>
            </y>
            <z>
              <noise type="gaussian">
                <mean>0.0</mean>
                <stddev>1.7e-2</stddev>
                <bias_mean>0.1</bias_mean>
                <bias_stddev>0.001</bias_stddev>
              </noise>
            </z>
          </linear_acceleration>
        </imu>
        <always_on>1</always_on>
        <update_rate>200</update_rate>
      </sensor>
    </link>
  </model>

  <model name="imu1">
    <link name="link">
     <pose>-1 0 0.05 0 0 0</pose>
      <inertial>
        <mass>0.1</mass>
      </inertial>
      <visual name="visual">
        <geometry>
          <box>
            <size>0.1 0.1 0.1</size>
          </box>
        </geometry>
      </visual>
      <collision name="collision">
        <geometry>
          <box>
            <size>0.1 0.1 0.1</size>
          </box>
        </geometry>
      </collision>
      <sensor name="imu" type="imu">
        <imu>
          <angular_velocity>
            <x>
              <noise type="gaussian">
                <mean>0.0</mean>
                <stddev>2e-4</stddev>
                <bias_mean>0.0000075</bias_mean>
                <bias_stddev>0.0000008</bias_stddev>
              </noise>
            </x>
            <y>
              <noise type="gaussian">
                <mean>0.0</mean>
                <stddev>2e-4</stddev>
                <bias_mean>0.0000075</bias_mean>
                <bias_stddev>0.0000008</bias_stddev>
              </noise>
            </y>
            <z>
              <noise type="gaussian">
                <mean>0.0</mean>
                <stddev>2e-4</stddev>
                <bias_mean>0.0000075</bias_mean>
                <bias_stddev>0.0000008</bias_stddev>
              </noise>
            </z>
          </angular_velocity>
          <linear_acceleration>
            <x>
              <noise type="gaussian">
                <mean>0.0</mean>
                <stddev>1.7e-2</stddev>
                <bias_mean>0.1</bias_mean>
                <bias_stddev>0.001</bias_stddev>
              </noise>
            </x>
            <y>
              <noise type="gaussian">
                <mean>0.0</mean>
                <stddev>1.7e-2</stddev>
                <bias_mean>0.1</bias_mean>
                <bias_stddev>0.001</bias_stddev>
              </noise>
            </y>
            <z>
              <noise type="gaussian">
                <mean>0.0</mean>
                <stddev>1.7e-2</stddev>
                <bias_mean>0.1</bias_mean>
                <bias_stddev>0.001</bias_stddev>
              </noise>
            </z>
          </linear_acceleration>
        </imu>
        <always_on>1</always_on>
        <update_rate>200</update_rate>
      </sensor>
    </link>
  </model>

  <model name="hokuyo0">
    <link name="link">
     <pose>-2 -2 0.05 0 0 0</pose>
      <gravity>false</gravity>
      <inertial>
        <mass>0.1</mass>
      </inertial>
      <visual name="visual">
        <geometry>
          <mesh>
            <uri>model://hokuyo/meshes/hokuyo.dae</uri>
          </mesh>
        </geometry>
      </visual>
      <sensor name="laser" type="ray">
        <pose>0.01 0 0.03 0 -0 0</pose>
        <ray>
          <scan>
            <horizontal>
              <samples>640</samples>
              <resolution>1</resolution>
              <min_angle>-3.14</min_angle>
              <max_angle>3.14</max_angle>
            </horizontal>
          </scan>
          <range>
            <min>0.08</min>
            <max>10</max>
            <resolution>0.01</resolution>
          </range>
          <noise>
            <type>gaussian</type>
            <mean>0.0</mean>
            <stddev>0.01</stddev>
          </noise>
        </ray>
        <always_on>1</always_on>
        <update_rate>200</update_rate>
        <visualize>true</visualize>
      </sensor>
    </link>
  </model>

  <model name="hokuyo1">
    <link name="link">
     <pose>2 2 0.05 0 0 0</pose>
      <gravity>false</gravity>
      <inertial>
        <mass>0.1</mass>
      </inertial>
      <visual name="visual">
        <geometry>
          <mesh>
            <uri>model://hokuyo/meshes/hokuyo.dae</uri>
          </mesh>
        </geometry>
      </visual>
      <sensor name="laser" type="ray">
        <pose>0.01 0 0.03 0 -0 0</pose>
        <ray>
          <scan>
            <horizontal>
              <samples>640</samples>
              <resolution>1</resolution>
              <min_angle>-3.14</min_angle>
              <max_angle>3.14</max_angle>
            </horizontal>
          </scan>
          <range>
            <min>0.08</min>
            <max>10</max>
            <resolution>0.01</resolution>
          </range>
          <noise>
            <type>gaussian</type>
            <mean>0.0</mean>
            <stddev>0.01</stddev>
          </noise>
        </ray>
        <always_on>1</always_on>
        <update_rate>200</update_rate>
        <visualize>true</visualize>
      </sensor>
    </link>
  </model>

  <model name="velodyne">
      <pose>-3 0 0.1 0 0 0</pose>
      <link name="link">
        <inertial>
          <mass>0.1</mass>
        </inertial>

        <collision name="collision">
          <geometry>
            <box>
              <size>0.2 0.2 0.2</size>
            </box>
          </geometry>
        </collision>

        <visual name="visual">
          <geometry>
            <box>
              <size>0.2 0.2 0.2</size>
            </box>
          </geometry>
        </visual>

        <sensor name="laser" type="ray">
          <pose>0.01 0 0.0175 0 -0 0</pose>
          <ray>
            <scan>
              <horizontal>
                <samples>640</samples>
                <resolution>1</resolution>
                <min_angle>-2.26889</min_angle>
                <max_angle>2.268899</max_angle>
              </horizontal>
              <vertical>
                <samples>32</samples>
                <resolution>1</resolution>
                <min_angle>-0.535</min_angle>
                <max_angle>0.186132</max_angle>
              </vertical>
            </scan>
            <range>
              <min>0.1</min>
              <max>10</max>
              <resolution>0.01</resolution>
            </range>
          </ray>

          <always_on>1</always_on>
          <update_rate>200</update_rate>
          <visualize>true</visualize>
        </sensor>
      </link>
    </model>

    <plugin name="GazeboPlugin" filename="lib/libGazeboCoSimPlugin.so"><portNumber>14581</portNumber></plugin>
  </world>
</sdf>
